Workbook

Sheet Summary Sheet
B2: Medivation Bio Private Limited | J2: Medivation Bio Private Limited
B3: Management_Report_(Funds Utilization Sheet)_upto_20th_July_2026 | J3: Management_Report_(Funds Utilization Sheet)_upto_30th_November_2025
B5: Particulars | C5: Ref | D5: Amount | E5: Particulars | F5: Ref | G5: Amount | J5: Particulars | K5: RAJ | L5: JAM | M5: Particulars | N5: RAJ | O5: JAM
B6: Utilization of Funds | E6: Sources of Funds | J6: Utilization of Funds | M6: Sources of Funds
B8: Capital Expenditure | E8: Promoters | J8: Capital Expenditure | M8: Promoters
B9: -----Furniture | C9: A | D9: =A!E21 -> 5783888.6 | E9: -------Parv Goyal | F9: K | G9: =L!E27 -> 3215000 | J9: -----Furniture | M9: -------Parv Goyal | N9: 0 | O9: 3215000
B10: -----Machinery | C10: B | D10: =B!E223 -> 3.8401272e+08 | E10: -------Ankit Bansal | F10: K | G10: =L!E46 -> 64825000 | J10: -----Machinery | M10: -------Ankit Bansal | N10: 0 | O10: 64825000
B11: -----Plant Land and Govt. Charges | C11: C | D11: ='C'!E11 -> 29301905 | E11: -------Aathesh Ventures Pvt Ltd | F11: K | G11: =L!E159 -> 322750000 | J11: -----Plant Land and Govt. Charges | M11: -------Aathesh Ventures Pvt Ltd | N11: 0 | O11: 204050000
B12: -----Office Equipment | C12: D | D12: =D!E40 -> 1678386.9 | E12: -------Divya Chadha | F12: K | G12: =L!E57 -> 3001000 | J12: -----Office Equipment | M12: -------Divya Chadha | N12: 0 | O12: 3001000
B13: -----Computer and Laptop | C13: E | D13: =E!E14 -> 721959.47 | E13: -------Share capital Introduced | F13: - | G13: 100000 | J13: -----Computer and Laptop | M13: -------Share capital Introduced | N13: 100000 | O13: 0
B14: -----Building Construction | C14: F | D14: =F!E167 -> 22192115
B15: -----Electrical Equipment | C15: N | D15: =N!E20 -> 14553723
B16: -----Intangible Asset | C16: - | D16: 229500
B17: -----Capital Work in Process | C17: - | D17: 76717813
B18: -----Fixed Asset of Rajasathan | C18: - | D18: =5466669.46 -> 5466669.5
B19: -----Sale Interstate Rajasthan | C19: - | D19: -2571905
B21: Account Payables | E21: Loan/WC from Bank
B22: -----Advance to Supplier | C22: H | D22: =H!C57 -> 18784302 | E22: ------HDFC Bank ( Loan -99649763 ) | F22: K | G22: =L!E210 -> 315990855
B23: -----Vendor Outstanding | C23: H1 | D23: ='H1'!C62 -> -20347708 | E23: ------HDFC WC Term Loan O/S | F23: - | G23: -4490
J24: Account Payables | M24: Interest Income
J25: -----Advance to Supplier | K25: 0 | L25: 54657320 | M25: -----FD Interest
B26: Operating Expenditure | E26: Interest Income | J26: -----Vendor Outstanding | K26: 0 | L26: -6279020 | M26: -----Misc Income | N26: 1741
B27: -----Salaries & Wages Due for the Month of June'26 | C27: - | D27: -99242 | E27: -----FD Interest | F27: - | G27: 3234701
B28: -----Other Expense(Jammu) | C28: I | D28: =I!C143 -> 37913501 | E28: -----Misc Income | F28: - | G28: =6177+1741+9404.8+94.4 -> 17417.2
B29: -----Other Expense(Rajasthan) | C29: I1 | D29: ='I1'!C94 -> 21223617 | J29: Operating Expenditure | M29: Cash Payment to Vendor
B30: -----Others | C30: J | D30: =J!D17 -> 2578582.8 | J30: -----Salaries & Wages Due for the Month of Nov'25 | L30: -1342841 | M30: -----Cash Introduce and Vendors Payment | N30: -14391
B31: -----CWIP Expense (Rajasthan) | C31: - | D31: -20375458 | J31: -----Other Expense(Jammu) | K31: 0 | L31: =40757772.43-45892.59 -> 40711880
B33: Raw Material Stock | E33: Cash Payment to Vendor | J33: -----Other Expense(Rajasthan) | K33: =20996305.25-74787.76 -> 20921517
B34: -----Raw Material-Stock | C34: G | D34: =G!C19 -> 28162669 | E34: -----Cash Introduce and Vendors Payment | F34: M | G34: =M!G16 -> 8483.09 | J34: -----Others | K34: 1000 | L34: =-184097+319483-(37243-285556-56250) -> 439949
B36: Duties and Taxes | J36: -----CWIP-Other Expense | K36: -20192877
B37: -----GST Input Jammu | C37: - | D37: 59061713
B38: -----GST Input Rajasthan | C38: - | D38: =750805.25-1500 -> 749305.25
B39: -----Other | C39: J | D39: =J!D6 -> 446.26
J40: Duties and Taxes
B41: Balance Available in Bank | J41: -----GST Input | K41: =729291.76-1500 -> 727791.76
B42: -----FD with HDFC Bank | C42: - | D42: 42633627 | J42: -----Other Receivables
B43: -----Balance in HDFC A/c- 99965 | C43: - | D43: =2622918.45-1116073 -> 1506845.5
B44: -----Balance in HDFC A/c - 7342 | C44: - | D44: 3251874 | J44: Balance Available in Bank
J45: -----FD with HDFC Bank (New)
B46: Suspense Entries | C46: K | D46: =K!C5 -> 0 | J46: -----Balance in HDFC A/c- 99965
...

Sheet A
B2: Furniture
B4: Date | C4: PARTICULARS | D4: Nature | E4: Amount
B5: 45561 | C5: NEW LOOOK FURNITURE INDUSTRY | D5: Office Furniture | E5: 53389.82
B6: 45820 | C6: NEW LOOOK FURNITURE INDUSTRY | D6: Office Furniture | E6: 29661.02
B7: 46192 | C7: NEW LOOOK FURNITURE INDUSTRY | D7: Office Furniture | E7: 29661.02
B8: 45654 | C8: MAGNUS KLEANTECH | D8: Plant Furniture | E8: 1086000
B9: 45654 | C9: MAGNUS KLEANTECH | D9: Plant Furniture | E9: 988550
B10: 45709 | C10: MAGNUS KLEANTECH | D10: Plant Furniture | E10: 364729.68
B11: 45743 | C11: MAGNUS KLEANTECH | D11: Plant Furniture | E11: 315554.4
B12: 45743 | C12: MAGNUS KLEANTECH | D12: Plant Furniture | E12: 370717.2
B13: 45855 | C13: RS CUBE PROJECTS PRIVATE LIMITED | D13: Plant Furniture | E13: 291070.42
B14: 45907 | C14: MAGNUS KLEANTECH | D14: Plant Furniture | E14: 358372
B15: 45907 | C15: MAGNUS KLEANTECH | D15: Plant Furniture | E15: 735098
B16: 45912 | C16: Brij Industries | D16: Plant Furniture | E16: 805085
... B19: 46151 | C19: MAGNUS KLEANTECH | D19: Plant Furniture | E19: 251000
C21: Total | E21: =SUM(E5:E19) -> 5783888.6

Sheet B
B2: Machinery
B4: Date | C4: Particulars | D4: Nature | E4: Amount
B5: 45405 | C5: Airwaves Projects Pvt. Ltd | D5: Machinery and Tools | E5: 213321.43
B6: 45407 | C6: Airwaves Projects Pvt. Ltd | D6: Machinery and Tools | E6: 1058198.4
B7: 45415 | C7: Airwaves Projects Pvt. Ltd | D7: Machinery and Tools | E7: 437838.24
B8: 45426 | C8: Khalsa Electric Co | D8: Machinery and Tools | E8: 12570.34
B9: 45428 | C9: Airwaves Projects Pvt. Ltd | D9: Machinery and Tools | E9: 692029.59
B10: 45430 | C10: Airwaves Projects Pvt. Ltd | D10: Machinery and Tools | E10: 786387
B11: 45443 | C11: Airwaves Projects Pvt. Ltd | D11: Machinery and Tools | E11: 14800
B12: 45456 | C12: GMP Technical Solutions Pvt Ltd | D12: Machinery and Tools | E12: 845371.9
B13: 45457 | C13: GMP Technical Solutions Pvt Ltd | D13: Machinery and Tools | E13: 642567.05
B14: 45457 | C14: GMP Technical Solutions Pvt Ltd | D14: Machinery and Tools | E14: 791035.25
B15: 45463 | C15: GMP Technical Solutions Pvt Ltd | D15: Machinery and Tools | E15: 822612.4
B16: 45467 | C16: GMP Technical Solutions Pvt Ltd | D16: Machinery and Tools | E16: 534640.9
... B221: 46214 | C221: Mep Contract and Services | D221: Machinery and Tools | E221: 638400
C223: Total | E223: =SUM(E5:E221) -> 3.8401272e+08

Sheet C
B2: Plant Land and Govt. Charges
B3: Date | C3: Particulars | D3: Nature | E3: Amount
B4: 45449 | C4: J & K SIDCO LTD 250 | D4: Govt. Charges | E4: 2071000
B5: 45492 | C5: J & K SIDCO LTD 250 | D5: Govt. Charges | E5: 105805
B6: 45492 | C6: J & K SIDCO LTD 250 | D6: Govt. Charges | E6: 200
B7: 45492 | C7: J & K SIDCO LTD 250 | D7: Govt. Charges | E7: 15000
B8: 45852 | C8: Director TTC Wing-Electrical Inspection Department | D8: Inspection Charges | E8: 9900
B9: 45017 | C9: Medivation-Rajsthan | D9: Jammu Land | E9: 27100000
C11: Total | E11: =SUM(E4:E9) -> 29301905

Sheet D
B1: Office Equipment
B3: Date | C3: Particulars | D3: Nature | E3: Amount
B4: 45311 | C4: Source Peripherals | D4: Office Equipment | E4: 33050.85
B5: 45398 | C5: Global Village | D5: Office Equipment | E5: 129244
B6: 45453 | C6: Maha Lakshmi Motors | D6: Office Equipment | E6: 48690.42
B7: 45581 | C7: Medivation-Rajsthan | D7: Office Equipment | E7: 1731405
B8: 45686 | C8: Maha Lakshmi Motors | D8: Office Equipment | E8: 13347.46
B9: 45689 | C9: Medivation-Rajsthan | D9: Office Equipment | E9: 840500
B10: 45689 | C10: Jammu Expense | D10: Office Equipment | E10: -2571905
B11: 45723 | C11: Clicktech Retail Private Limited | D11: Office Equipment | E11: 8473.73
B12: 45723 | C12: Dawntech Electronics Private Limited | D12: Office Equipment | E12: 26554.69
B13: 45723 | C13: Dawntech Electronics Private Limited | D13: Office Equipment | E13: 11601.69
B14: 45723 | C14: Retailez Private Limited | D14: Office Equipment | E14: 2372.03
B15: 45723 | C15: Retailez Private Limited | D15: Office Equipment | E15: 2541.53
... B38: 46158 | C38: Power Vista Technologies | D38: Office Equipment | E38: 352600
C40: Total | E40: =SUM(E4:E38) -> 1678386.9

Sheet E
B1: Computer and Laptop
B3: Date | C3: Particulars | D3: Nature | E3: Amount
B4: 45587 | C4: ELEGANT COMMUNICATIONS | D4: Computer and Laptop | E4: 71959.32
B5: 45729 | C5: SABHAYA COMPUTERS | D5: Computer and Laptop | E5: 92796.2
B6: 45729 | C6: SABHAYA COMPUTERS | D6: Computer and Laptop | E6: 152542.38
B7: 45738 | C7: SABHAYA COMPUTERS | D7: Computer and Laptop | E7: 101694.92
B8: 45821 | C8: SABHAYA COMPUTERS | D8: Computer and Laptop | E8: 73728.81
B9: 45865 | C9: SABHAYA COMPUTERS | D9: Computer and Laptop | E9: 77966.1
B10: 46177 | C10: Quantum Technologies | D10: Computer and Laptop | E10: 50848
B11: 46106 | C11: Quantum Technologies | D11: Computer and Laptop | E11: 66949.16
B12: 46106 | C12: Quantum Technologies | D12: Computer and Laptop | E12: 33474.58
C14: Total | E14: =SUM(E4:E12) -> 721959.47

Sheet F
B2: Building Construction
B4: Air Conditioner
B5: Date | C5: Particulars | D5: Nature | E5: Amount
B6: 45437 | C6: Bahu Electronics | D6: Air Conditioner | E6: 28522.25
B7: 45558 | C7: AGGARWAL AGENCIES | D7: Air Conditioner | E7: 44531.25
B8: 45581 | C8: Tempcon Air Systems | D8: Air Conditioner | E8: 474317.19
B9: 45793 | C9: AGGARWAL AGENCIES | D9: Air Conditioner | E9: 575500
B10: 45815 | C10: PRECISION SYSTEMS | D10: Air Conditioner | E10: 334080
B11: 45818 | C11: AGGARWAL AGENCIES | D11: Air Conditioner | E11: 44531.25
B12: 45835 | C12: PRECISION SYSTEMS | D12: Air Conditioner | E12: 112666.4
C14: Total | E14: =SUM(E6:E12) -> 1614148.3
B16: Asset-Lal Sai
B17: Date | C17: Particulars | D17: Nature | E17: Amount
B18: 45311 | C18: Lal Sai Steel | D18: Assets- Lal Sai | E18: 1287300
B19: 45312 | C19: Lal Sai Steel | D19: Assets- Lal Sai | E19: 623329.66
B20: 45322 | C20: Lal Sai Steel | D20: Assets- Lal Sai | E20: 87082.2
B21: 45355 | C21: Lal Sai Steel | D21: Assets- Lal Sai | E21: 1222115.2
B22: 45384 | C22: Lal Sai Steel | D22: Assets- Lal Sai | E22: 465800
B23: 45385 | C23: Lal Sai Steel | D23: Assets- Lal Sai | E23: 483384.75
B24: 45386 | C24: Lal Sai Steel | D24: Assets- Lal Sai | E24: 234018.64
B25: 45442 | C25: Lal Sai Steel | D25: Assets- Lal Sai | E25: 70435.59
B26: 45447 | C26: Lal Sai Steel | D26: Assets- Lal Sai | E26: 38203.39
B27: 45448 | C27: Lal Sai Steel | D27: Assets- Lal Sai | E27: 54166.95
B28: 45478 | C28: Lal Sai Steel | D28: Assets- Lal Sai | E28: 2029443.2
B29: 45478 | C29: Lal Sai Steel | D29: Assets- Lal Sai | E29: 638820.34
... B39: 45943 | C39: Lal Sai Steel | D39: Assets- Lal Sai | E39: 383400
C41: Total | E41: =SUM(E18:E39) -> 11604471
B43: Building Construction
B44: Date | C44: Particulars | D44: Nature | E44: Amount
B45: 45423 | C45: Rishil Marble | D45: Building Construction | E45: 239160
B46: 45426 | C46: Davinder Iron & Steel Co. | D46: Building Construction | E46: 8561.86
B47: 45427 | C47: Aone Metal Industries | D47: Building Construction | E47: 1553.39
B48: 45427 | C48: Metal Dreams Industries | D48: Building Construction | E48: 8801.69
B49: 45428 | C49: Lalotra Sales Corporation | D49: Building Construction | E49: 1094.92
B50: 45444 | C50: K R Enterprises | D50: Building Construction | E50: 95409.33
B51: 45451 | C51: K R Enterprises | D51: Building Construction | E51: 45861.86
B52: 45453 | C52: K R Enterprises | D52: Building Construction | E52: 9806.78
B53: 45453 | C53: K R Enterprises | D53: Building Construction | E53: -8883.05
B54: 45454 | C54: Rishil Marble | D54: Building Construction | E54: 190380
B55: 45456 | C55: Delhi Building Material Corporation | D55: Building Construction | E55: 4883.9
...

Sheet N
B1: -----Electrical Equipment
B3: Date | C3: Particulars | D3: Nature | E3: Amount
B4: 45579 | C4: N.T Electricals | D4: Electrical Equipment | E4: 3212475
B5: 45585 | C5: N.T Electricals | D5: Electrical Equipment | E5: 1525240
B6: 45631 | C6: N.T Electricals | D6: Electrical Equipment | E6: 573250
B7: 45631 | C7: N.T Electricals | D7: Electrical Equipment | E7: 2500000
B8: 45642 | C8: N.T Electricals | D8: Electrical Equipment | E8: 289750
B9: 45660 | C9: N.T Electricals | D9: Electrical Equipment | E9: 1334500
B10: 45668 | C10: N.T Electricals | D10: Electrical Equipment | E10: 2376500
B11: 45717 | C11: N.T Electricals | D11: Electrical Equipment | E11: 294700
B12: 45726 | C12: N.T Electricals | D12: Electrical Equipment | E12: 40000
B13: 45732 | C13: N.T Electricals | D13: Electrical Equipment | E13: 127400
B14: 45814 | C14: N.T Electricals | D14: Electrical Equipment | E14: 219625
B15: 45845 | C15: N.T Electricals | D15: Electrical Equipment | E15: 15000
... B18: 46118 | C18: N.T Electricals | D18: Electrical Equipment | E18: 268615
C20: Total | E20: =SUM(E4:E18) -> 14553723

Sheet G
B1: Raw Material
B3: Particular | C3: Amount
B4: Purchase Accounts | C4: =SUM(C5:C10) -> 6756337.7
B5: Local Purchase@18% | C5: 2389549.5
B6: Local Purchase@5% | C6: 137280
B7: Local Purchase @5% IGST | C7: 262240
B8: Purchase Discount Received | C8: -15674
B9: Purchase IGST @18% | C9: 3978742.2
B10: Purchase – Medical Consumables | C10: 4200
B12: Direct Expenses | C12: =SUM(C13:C17) -> 21406331
B13: Packaging Material | C13: 196694.45
B14: Raw Material | C14: 21062783
B15: Consumable Itmes 18% | C15: 112455.77
B16: Consumable Itmes 5% | C16: 30400
B17: Medical Items | C17: 3998.07
B19: Grand Total | C19: =C12+C4 -> 28162669

Sheet H
B1: Advance to Supplier
B3: Particulars | C3: Amount
B4: Air India-Baroda | C4: 23962
B5: Air India - Gurgaon | C5: 20278
B6: Tyco Electronics Middle East Fze | C6: 619234.93
B7: Magnus Kleantech | C7: 612313.49
B8: RS Cube Projects Private Limited | C8: 120169
B9: AS . Enterprises | C9: 1131500
B10: Ashish Enterprises | C10: 1924280
B11: BHAGWATI ENTERPRISES | C11: 5500
B12: COFFEE DAY GLOBAL LIMITED | C12: 26000
B13: Cost 2 Cost Computer | C13: 58700
B14: Country Inn & Suites (Radisson) Hotel | C14: 9104
B15: DHL- Express Pvt Ltd - Courier Service | C15: 549.01
... B55: Uber India System Pvt Ltd | C55: 731.37
B57: Grand Total | C57: =SUM(C4:C55) -> 18784302
C63: Debit | D63: Credit
B64: Other Creditors | C64: 44240 | D64: 287711.67
B65: Air India-Baroda | C65: 23962
B66: Air India - Gurgaon | C66: 20278
B67: Air India Limited-Delhi | D67: 21958
B68: Air India Limited -Kerala | D68: 18785.3
B69: Interglobe Aviation Limited ( Jammu ) | D69: 108911
B70: Interglobe Aviation Limited-Mumbai | D70: 7331.1
B71: Interglobe Aviation Limited ( New Delhi ) | D71: 95734.25
B72: Make My Trip (India) Pvt. Ltd.- Gurgaon | D72: 4562.02
B73: National Aviation Company of India Ltd -Jammu | D73: 14638
B74: Spicejet Limited | D74: 15792
B75: Amazon Creditors
B76: Foreign Creditors | C76: 619234.93 | D76: 3165021.9
B77: Allied Way (Hk) Limited | D77: 2502531.5
B78: BlockWise Enginnering LLC_x000D_ | D78: 2975.91
B79: Resonetics Medelec | D79: 346098.14
B80: Shanghai INT Medical Instruments Co., Ltd | D80: 313416.35
B81: Tyco Electronics Middle East Fze | C81: 619234.93
B82: Furniture Creditors | C82: 732482.49
B83: Magnus Kleantech | C83: 612313.49
B84: RS Cube Projects Private Limited | C84: 120169
B85: Insurance Creditors | D85: 20798.68
B86: ICICI Lombard General Insurance | D86: 20798.68
...

Sheet H1
B1: Vendor Outstanding
B3: Particulars | C3: Amount
B4: Air India Limited-Delhi | C4: 21958
B5: Air India Limited -Kerala | C5: 18785.3
B6: Interglobe Aviation Limited ( Jammu ) | C6: 108911
B7: Interglobe Aviation Limited-Mumbai | C7: 7331.1
B8: Interglobe Aviation Limited ( New Delhi ) | C8: 95734.25
B9: Make My Trip (India) Pvt. Ltd.- Gurgaon | C9: 4562.02
B10: National Aviation Company of India Ltd -Jammu | C10: 14638
B11: Spicejet Limited | C11: 15792
B12: Allied Way (Hk) Limited | C12: 2502531.5
B13: BlockWise Enginnering LLC_x000D_ | C13: 2975.91
B14: Resonetics Medelec | C14: 346098.14
B15: Shanghai INT Medical Instruments Co., Ltd | C15: 313416.35
... B60: -----Rajasthan Creditors | C60: 50534.37
B62: TOTAL | C62: =-SUM(C4:C60) -> -20347708

Sheet I
B4: Particular | C4: Amount
B5: Administration | C5: =SUM(C6:C8) -> 153032.81
B6: ADMINISTRATION CHARGES | C6: 30104
B7: Printing and Stationery | C7: 30528.81
B8: Website Maintenance | C8: 92400
B10: Bank Guarantee Charges | C10: 9558
B11: BG Commission & Other Charges | C11: 9558
B13: Business Promotion | C13: =SUM(C14:C15) -> 103718.65
B14: MARSHALL EMBERTON || MS-EMBRN-2 | C14: 55667.8
B15: MARSHAL WILLEN BLK-BRS | C15: 48050.85
B17: Consumables & Supplies_x000D_ | C17: 224.42
B18: Decoration Items | C18: 224.42
B20: Financial Charges & Income_x000D_ | C20: =SUM(C21:C26) -> 6195047.6
B21: Bank Charges | C21: 22496.68
B22: Bank Charges- Commission ( On Import of Goods) | C22: 37040.44
B23: Bank Charges ( Make My Trip ) | C23: 6440
B24: Forex Gain/Loss | C24: -1278377.5
B25: Interest on Term Loan | C25: 7379055
B26: Pre Emi Interest Charge | C26: 28393
B28: Freight & Logistics_x000D_ | C28: =SUM(C29:C37) -> 2027144.1
B29: Bonded Storage | C29: 6354
B30: CLEARANCE CHARGES | C30: 35720
B31: COURIER SERVICE_x000D_ | C31: 436555.08
B32: DISBURSEMENT FEE ( DHL Import ) | C32: 7993.32
B33: Freight Inward Charges | C33: 674135.16
B34: Freight Outward Charges | C34: 6000
B35: IMPORT EXPORT DUTIES | C35: 13710.37
B36: SW SURCHARGE | C36: 93537
B37: Transportation Charges | C37: 753139.15
B39: Hotel Expenses | C39: =SUM(C40:C41) -> 151189.4
B40: Hotel Stay Charges | C40: 100655.59
B41: Hotel Stay Expense (NEW) | C41: 50533.81
B43: Insurance | C43: =SUM(C44:C46) -> 1982082.1
B44: Health Insurances | C44: 1652054.3
B45: Insurance | C45: 230288.8
B46: Property Insurance | C46: 99739
B48: Operating Expenses (Indirect)_x000D_ | C48: =SUM(C49:C70) -> 7213339.4
B49: Amazon Prime Membership | C49: 1499
B50: APPLICATION CHARGERS | C50: 16236
B51: Bills Not Yet Received | C51: 43220
...

Sheet I1
B1: Particular | C1: Amount
B2: Administration | C2: =SUM(C3:C5) -> 14817.2
B3: Printing & stationery | C3: 7727
B4: Printing & stationery- 12% | C4: 1992.86
B5: Printing & stationery- 18% | C5: 5097.34
B7: Business Promotion | C7: =SUM(C8:C9) -> 42713.86
B8: Business Promotion | C8: 42713.86
B10: Consumables & Supplies | C10: =SUM(C11:C13) -> 29781.74
B11: CONSUMABLE 12% | C11: 3928.54
B12: Consumable Items | C12: 25853.2
B14: Financial Charges | C14: =SUM(C15:C19) -> 688465.85
B15: Bank Charges | C15: 19141.85
B16: CERTIFICATION CHARGES | C16: 10000
B17: Dsc Charges | C17: 5000
B18: ROC-Stamp Duty | C18: 654324
B20: Freight & Logistics | C20: =SUM(C21:C25) -> 205858.74
B21: Air Freight | C21: 116055
B22: Forex Gain/Loss | C22: 3707.74
B23: FREIGHT CHARGES | C23: 196
B24: Inward Expenses | C24: 900
B25: Transportation Expenes | C25: 85000
B27: Guest House Rent | C27: =SUM(C28:C30) -> 703282.36
B28: RENT EXPENSE | C28: 543282.36
B29: Rent Jummu Guest House | C29: 160000
B31: Hotel Expenses | C31: =SUM(C32:C32) -> 25219
B32: Hotel Stay Charges | C32: 25219
B34: Office Expenses | C34: =SUM(C35:C42) -> 312473.1
B35: Computer Mouse | C35: 7711.88
B36: Mi Tv Stick with Built In Chromecast | C36: 2541.53
B37: Office Expence 5% | C37: 10590.48
B38: Office Expense Non GST | C38: 51585.23
B39: Office Expenses | C39: 143398.18
B40: Office Expesne -12% | C40: 13644.64
B41: Office Expesne -GST | C41: 79568.96
B42: Pan Drive | C42: 3432.2
B44: Operating Expenses (Indirect) | C44: =SUM(C45:C69) -> 16378379
B45: Activation Charges | C45: 1000
B46: Adoptor | C46: 1178.72
B47: Amazon Prime (Yearly Membership) | C47: 1499
B48: Application Charges | C48: 77961.26
...

Sheet J
B2: Other Receivables
B3: Unit | C3: Particular | D3: Amount
B4: Jammu | C4: TDS on contractor | D4: 446.26
C6: Total | D6: =SUM(D4:D4) -> 446.26
B8: Others
B9: Unit | C9: Particular | D9: Amount
B10: Jammu | C10: Parv Goyal card | D10: 138128.13
B11: Jammu | C11: Parv Goyal Imprest | D11: -365579.96
B12: Jammu | C12: FD Interest Accrured | D12: 2398127
B13: Jammu | C13: Rent Security | D13: 190000
B14: RJ | C14: Secuity Deposit-wifi | D14: 1000
B15: Jammu | C15: TDS RECEVIBLES | D15: 216907.6
C17: Total | D17: =SUM(D10:D15) -> 2578582.8

Sheet K
A1: SUSPENSE ENTRIES
A3: Date | B3: Particulars | C3: Gross Total | D3: Remarks
B4: Nil
C5: =SUM(C4:C4) -> 0

Sheet L
B2: -------Parv Goyal
B3: Date | C3: Particulars | D3: Vch Type | E3: Debit | F3: Credit
B4: 44705 | C4: Kotak Mahindra Bank A/c 8545603885 | D4: Receipt | F4: 100000
B5: 44707 | C5: Kotak Mahindra Bank A/c 8545603885 | D5: Receipt | F5: 500000
B6: 44716 | C6: Kotak Mahindra Bank A/c 8545603885 | D6: Receipt | F6: 500000
B7: 44739 | C7: Kotak Mahindra Bank A/c 8545603885 | D7: Receipt | F7: 500000
B8: 44746 | C8: Kotak Mahindra Bank A/c 8545603885 | D8: Receipt | F8: 300000
B9: 44766 | C9: Kotak Mahindra Bank A/c 8545603885 | D9: Payment | E9: 25000
B10: 44769 | C10: Kotak Mahindra Bank A/c 8545603885 | D10: Receipt | F10: 500000
B11: 44774 | C11: Kotak Mahindra Bank A/c 8545603885 | D11: Receipt | F11: 500000
B12: 44795 | C12: Kotak Mahindra Bank A/c 8545603885 | D12: Receipt | F12: 500000
B13: 44795 | C13: Kotak Mahindra Bank A/c 8545603885 | D13: Receipt | F13: 500000
B14: 44831 | C14: Kotak Mahindra Bank A/c 8545603885 | D14: Payment | E14: 500000
B15: 44831 | C15: Kotak Mahindra Bank A/c 8545603885 | D15: Payment | E15: 500000
B16: 44832 | C16: Kotak Mahindra Bank A/c 8545603885 | D16: Payment | E16: 500000
B17: 44832 | C17: Kotak Mahindra Bank A/c 8545603885 | D17: Payment | E17: 500000
B18: 44833 | C18: Kotak Mahindra Bank A/c 8545603885 | D18: Payment | E18: 500000
B19: 44833 | C19: Kotak Mahindra Bank A/c 8545603885 | D19: Payment | E19: 500000
B20: 44833 | C20: Kotak Mahindra Bank A/c 8545603885 | D20: Payment | E20: 150000
B21: 44834 | C21: Kotak Mahindra Bank A/c 8545603885 | D21: Payment | E21: 500000
B22: 44879 | C22: HDFC BANK 99999999999965 | D22: Receipt | F22: 2500000
B23: 44879 | C23: HDFC BANK 99999999999965 | D23: Receipt | F23: 2490000
B24: 44883 | C24: HDFC BANK 99999999999965 | D24: Payment | E24: 2000000
C26: Total | E26: =SUM(E4:E25) -> 5675000 | F26: =SUM(F4:F25) -> 8890000
C27: Closing Balance | E27: =F26-E26 -> 3215000
B30: ------Ankit Bansal
B31: Date | C31: Particulars | D31: Vch Type | E31: Debit | F31: Credit
B32: 44287 | C32: Opening Balance | F32: 10000
B33: 45173 | C33: HDFC BANK 99999999999965 | D33: Receipt | F33: 10200000
B34: 45474 | C34: HDFC BANK 99999999999965 | D34: Receipt | F34: 5000000
B35: 45475 | C35: HDFC BANK 99999999999965 | D35: Receipt | F35: 5000000
B36: 45475 | C36: HDFC 50200098257342 | D36: Receipt | F36: 700000
B37: 45492 | C37: HDFC 50200098257342 | D37: Receipt | F37: 2000000
B38: 45547 | C38: HDFC BANK 99999999999965 | D38: Receipt | F38: 10000000
B39: 45565 | C39: HDFC BANK 99999999999965 | D39: Receipt | F39: 10000000
B40: 45632 | C40: HDFC BANK 99999999999965 | D40: Receipt | F40: 10000000
B41: 45679 | C41: HDFC BANK 99999999999965 | D41: Receipt | F41: 3000000
B42: 45686 | C42: HDFC BANK 99999999999965 | D42: Receipt | F42: 2315000
B43: 45848 | C43: HDFC BANK 99999999999965 | D43: Receipt | F43: 5000000
B44: 45936 | C44: HDFC BANK 99999999999965 | D44: Receipt | F44: 1600000
...

Sheet M
B2: List of Vendors/ Expeses paid through Cash but no cash withdrawl from Bank
B4: Date | C4: Particulars | D4: Vch Type | E4: Vch No. | F4: Debit | G4: Credit
B5: Closing Bal. | C5: Medivation Rajasthan | D5: Payment | E5: - | F5: 14391
B6: 45747 | C6: Parv Goyal imprest | D6: Journal | E6: - | F6: 10000
B7: 45748 | C7: Khalsa Electric Co | D7: Payment | E7: - | G7: 14833
B8: 45748 | C8: Khalsa Electric Co | D8: Payment | E8: - | G8: 10240
B9: 45873 | C9: Reliant Packaging Films Private Ltd | D9: Payment | E9: - | G9: 991
B10: 45912 | C10: Chinar Roadlines (Regd.) | D10: Payment | E10: - | G10: 46715
B11: 45934 | C11: TCI Freight | D11: Journal | E11: - | G11: 100
B12: 45957 | C12: VTrans (India) Limited | D12: Payment | E12: - | G12: 1614
B13: 46112 | C13: Parv Goyal imprest-II | D13: Journal | E13: - | F13: 41000
B14: 46112 | C14: Bombay Scientific Stores Pvt Ltd | D14: Journal | E14: - | F14: 618.91
C15: Total | F15: =SUM(F5:F14) -> 66009.91 | G15: =SUM(G5:G14) -> 74493
C16: Net Cash | G16: =G15-F15 -> 8483.09

Sheet F1(PARTY ADVANCE)
A3: Row Labels | B3: Sum of Amount
A4: Airwaves Project Private Limited | B4: 1820679
A5: AS Enterprise | B5: 1031500
A6: Ashish Enterprises | B6: 10467000
A7: Balay Safety Solutions | B7: 1924634
A8: BlockWise Enginnering LLC | B8: 153183.55
A9: BW TEC AG | B9: 47665746
A10: Controller Drug and food Control | B10: 12500
A11: Extrumed Inc Dba Vesta | B11: 729786.54
A12: Friends Medicure Pvt Ltd | B12: 9558 | C12: Bills received
A13: Kavita Gupta | B13: 20000 | C13: Trademark and copyright (Divya Mam)
A14: Lal Sai Steel | B14: 10658686 | C14: to be adjusted against bills
A15: Maa Constructions | B15: 2000000
A16: Machine Solutions INC | B16: 24156684
A17: MAGNUS KLEANTECH | B17: 2851442 | C17: bill received
A18: Maxwell Exports | B18: 2002000
A19: N T ELECRICALS | B19: 1965104 | C19: Bills received
A20: N.T.ELECTRICALS | B20: 7835574 | C20: Bills received
A21: Narola Machines | B21: 442500
A22: Niva Bupa Health Insurance | B22: 58551
A23: Parv Cardit Card | B23: 132655 | C23: to be expense off
A24: Pass Card Co Ltd | B24: 6961237.3
A25: PCI Pest Control Private Limited | B25: 29500
A26: Pentagon Assembly Automation Pvt Ltd | B26: 10000000
A27: RADIAINT INDUSTRIES | B27: 7200000
A28: RAJ ENTERPRISES | B28: 487627
A29: RESONETICS MEDELEC | B29: 1614122
A30: Rising Sun Enterprises | B30: 350734
A31: Safeway Technology | B31: 482800
A32: Samarth Electronices | B32: 29972
A33: Shibaura Machine India Pvt Ltd | B33: 11798500
A34: Spento Engineering | B34: 1152123
A35: STERILE SAFEQUIP AND CHEMICALS LLP | B35: 2920205 | C35: bill received
A36: The New India Assurance Co Ltd | B36: 52864
A37: ThermoLab Scientific Equipments Pvt Ltd | B37: 2053200 | C37: bill received
A38: Vesta Thermoplastics Divison | B38: 1556999.8
A39: ZEUS INDUSTRIAL PRODUTS | B39: 277340.09
A40: Grand Total | B40: =SUM(B3:B39) -> 1.6290501e+08
